supervisor: couldn't chdir to /homr/alexuserdev/crypto_exchange_bot: ENOENT
supervisor: child process was not spawned
supervisor: couldn't chdir to /homr/alexuserdev/crypto_exchange_bot: ENOENT
supervisor: child process was not spawned
supervisor: couldn't chdir to /homr/alexuserdev/crypto_exchange_bot: ENOENT
supervisor: child process was not spawned
supervisor: couldn't chdir to /homr/alexuserdev/crypto_exchange_bot: ENOENT
supervisor: child process was not spawned
supervisor: couldn't chdir to /homr/alexuserdev/crypto_exchange_bot: ENOENT
supervisor: child process was not spawned
supervisor: couldn't chdir to /homr/alexuserdev/crypto_exchange_bot: ENOENT
supervisor: child process was not spawned
supervisor: couldn't chdir to /homr/alexuserdev/crypto_exchange_bot: ENOENT
supervisor: child process was not spawned
supervisor: couldn't chdir to /homr/alexuserdev/crypto_exchange_bot: ENOENT
supervisor: child process was not spawned
supervisor: couldn't chdir to /homr/alexuserdev/crypto_exchange_bot: ENOENT
supervisor: child process was not spawned
python3.8: can't open file 'app.py': [Errno 2] No such file or directory
python3.8: can't open file 'app.py': [Errno 2] No such file or directory
python3.8: can't open file 'app.py': [Errno 2] No such file or directory
python3.8: can't open file 'app.py': [Errno 2] No such file or directory
Traceback (most recent call last):
  File "bot.py", line 4, in <module>
    from aiogram import Bot, Dispatcher
ModuleNotFoundError: No module named 'aiogram'
Traceback (most recent call last):
  File "bot.py", line 4, in <module>
    from aiogram import Bot, Dispatcher
ModuleNotFoundError: No module named 'aiogram'
Traceback (most recent call last):
  File "bot.py", line 4, in <module>
    from aiogram import Bot, Dispatcher
ModuleNotFoundError: No module named 'aiogram'
Traceback (most recent call last):
  File "bot.py", line 4, in <module>
    from aiogram import Bot, Dispatcher
ModuleNotFoundError: No module named 'aiogram'
Traceback (most recent call last):
  File "bot.py", line 4, in <module>
    from aiogram import Bot, Dispatcher
ModuleNotFoundError: No module named 'aiogram'
Traceback (most recent call last):
  File "bot.py", line 4, in <module>
    from aiogram import Bot, Dispatcher
ModuleNotFoundError: No module named 'aiogram'
Traceback (most recent call last):
  File "bot.py", line 4, in <module>
    from aiogram import Bot, Dispatcher
ModuleNotFoundError: No module named 'aiogram'
Traceback (most recent call last):
  File "bot.py", line 4, in <module>
    from aiogram import Bot, Dispatcher
ModuleNotFoundError: No module named 'aiogram'
bot.py [LINE:52] #INFO     [2021-08-08 13:38:40,107]  Starting bot
dispatcher.py [LINE:360] #INFO     [2021-08-08 13:38:40,129]  Start polling.
dispatcher.py [LINE:392] #ERROR    [2021-08-08 13:38:45,318]  Cause exception while getting updates.
Traceback (most recent call last):
  File "/usr/local/lib/python3.8/dist-packages/aiogram/dispatcher/dispatcher.py", line 383, in start_polling
    updates = await self.bot.get_updates(
  File "/usr/local/lib/python3.8/dist-packages/aiogram/bot/bot.py", line 97, in get_updates
    result = await self.request(api.Methods.GET_UPDATES, payload)
  File "/usr/local/lib/python3.8/dist-packages/aiogram/bot/base.py", line 208, in request
    return await api.make_request(self.session, self.server, self.__token, method, data, files,
  File "/usr/local/lib/python3.8/dist-packages/aiogram/bot/api.py", line 140, in make_request
    return check_result(method, response.content_type, response.status, await response.text())
  File "/usr/local/lib/python3.8/dist-packages/aiogram/bot/api.py", line 119, in check_result
    exceptions.ConflictError.detect(description)
  File "/usr/local/lib/python3.8/dist-packages/aiogram/utils/exceptions.py", line 140, in detect
    raise err(cls.text or description)
aiogram.utils.exceptions.TerminatedByOtherGetUpdates: Terminated by other getupdates request; make sure that only one bot instance is running
dispatcher.py [LINE:392] #ERROR    [2021-08-08 13:38:55,603]  Cause exception while getting updates.
Traceback (most recent call last):
  File "/usr/local/lib/python3.8/dist-packages/aiogram/dispatcher/dispatcher.py", line 383, in start_polling
    updates = await self.bot.get_updates(
  File "/usr/local/lib/python3.8/dist-packages/aiogram/bot/bot.py", line 97, in get_updates
    result = await self.request(api.Methods.GET_UPDATES, payload)
  File "/usr/local/lib/python3.8/dist-packages/aiogram/bot/base.py", line 208, in request
    return await api.make_request(self.session, self.server, self.__token, method, data, files,
  File "/usr/local/lib/python3.8/dist-packages/aiogram/bot/api.py", line 140, in make_request
    return check_result(method, response.content_type, response.status, await response.text())
  File "/usr/local/lib/python3.8/dist-packages/aiogram/bot/api.py", line 119, in check_result
    exceptions.ConflictError.detect(description)
  File "/usr/local/lib/python3.8/dist-packages/aiogram/utils/exceptions.py", line 140, in detect
    raise err(cls.text or description)
aiogram.utils.exceptions.TerminatedByOtherGetUpdates: Terminated by other getupdates request; make sure that only one bot instance is running
dispatcher.py [LINE:392] #ERROR    [2021-08-08 13:39:06,126]  Cause exception while getting updates.
Traceback (most recent call last):
  File "/usr/local/lib/python3.8/dist-packages/aiogram/dispatcher/dispatcher.py", line 383, in start_polling
    updates = await self.bot.get_updates(
  File "/usr/local/lib/python3.8/dist-packages/aiogram/bot/bot.py", line 97, in get_updates
    result = await self.request(api.Methods.GET_UPDATES, payload)
  File "/usr/local/lib/python3.8/dist-packages/aiogram/bot/base.py", line 208, in request
    return await api.make_request(self.session, self.server, self.__token, method, data, files,
  File "/usr/local/lib/python3.8/dist-packages/aiogram/bot/api.py", line 140, in make_request
    return check_result(method, response.content_type, response.status, await response.text())
  File "/usr/local/lib/python3.8/dist-packages/aiogram/bot/api.py", line 119, in check_result
    exceptions.ConflictError.detect(description)
  File "/usr/local/lib/python3.8/dist-packages/aiogram/utils/exceptions.py", line 140, in detect
    raise err(cls.text or description)
aiogram.utils.exceptions.TerminatedByOtherGetUpdates: Terminated by other getupdates request; make sure that only one bot instance is running
dispatcher.py [LINE:392] #ERROR    [2021-08-08 13:39:16,242]  Cause exception while getting updates.
Traceback (most recent call last):
  File "/usr/local/lib/python3.8/dist-packages/aiogram/dispatcher/dispatcher.py", line 383, in start_polling
    updates = await self.bot.get_updates(
  File "/usr/local/lib/python3.8/dist-packages/aiogram/bot/bot.py", line 97, in get_updates
    result = await self.request(api.Methods.GET_UPDATES, payload)
  File "/usr/local/lib/python3.8/dist-packages/aiogram/bot/base.py", line 208, in request
    return await api.make_request(self.session, self.server, self.__token, method, data, files,
  File "/usr/local/lib/python3.8/dist-packages/aiogram/bot/api.py", line 140, in make_request
    return check_result(method, response.content_type, response.status, await response.text())
  File "/usr/local/lib/python3.8/dist-packages/aiogram/bot/api.py", line 119, in check_result
    exceptions.ConflictError.detect(description)
  File "/usr/local/lib/python3.8/dist-packages/aiogram/utils/exceptions.py", line 140, in detect
    raise err(cls.text or description)
aiogram.utils.exceptions.TerminatedByOtherGetUpdates: Terminated by other getupdates request; make sure that only one bot instance is running
dispatcher.py [LINE:392] #ERROR    [2021-08-08 13:39:26,363]  Cause exception while getting updates.
Traceback (most recent call last):
  File "/usr/local/lib/python3.8/dist-packages/aiogram/dispatcher/dispatcher.py", line 383, in start_polling
    updates = await self.bot.get_updates(
  File "/usr/local/lib/python3.8/dist-packages/aiogram/bot/bot.py", line 97, in get_updates
    result = await self.request(api.Methods.GET_UPDATES, payload)
  File "/usr/local/lib/python3.8/dist-packages/aiogram/bot/base.py", line 208, in request
    return await api.make_request(self.session, self.server, self.__token, method, data, files,
  File "/usr/local/lib/python3.8/dist-packages/aiogram/bot/api.py", line 140, in make_request
    return check_result(method, response.content_type, response.status, await response.text())
  File "/usr/local/lib/python3.8/dist-packages/aiogram/bot/api.py", line 119, in check_result
    exceptions.ConflictError.detect(description)
  File "/usr/local/lib/python3.8/dist-packages/aiogram/utils/exceptions.py", line 140, in detect
    raise err(cls.text or description)
aiogram.utils.exceptions.TerminatedByOtherGetUpdates: Terminated by other getupdates request; make sure that only one bot instance is running
dispatcher.py [LINE:392] #ERROR    [2021-08-08 13:39:36,481]  Cause exception while getting updates.
Traceback (most recent call last):
  File "/usr/local/lib/python3.8/dist-packages/aiogram/dispatcher/dispatcher.py", line 383, in start_polling
    updates = await self.bot.get_updates(
  File "/usr/local/lib/python3.8/dist-packages/aiogram/bot/bot.py", line 97, in get_updates
    result = await self.request(api.Methods.GET_UPDATES, payload)
  File "/usr/local/lib/python3.8/dist-packages/aiogram/bot/base.py", line 208, in request
    return await api.make_request(self.session, self.server, self.__token, method, data, files,
  File "/usr/local/lib/python3.8/dist-packages/aiogram/bot/api.py", line 140, in make_request
    return check_result(method, response.content_type, response.status, await response.text())
  File "/usr/local/lib/python3.8/dist-packages/aiogram/bot/api.py", line 119, in check_result
    exceptions.ConflictError.detect(description)
  File "/usr/local/lib/python3.8/dist-packages/aiogram/utils/exceptions.py", line 140, in detect
    raise err(cls.text or description)
aiogram.utils.exceptions.TerminatedByOtherGetUpdates: Terminated by other getupdates request; make sure that only one bot instance is running
dispatcher.py [LINE:392] #ERROR    [2021-08-08 13:39:46,604]  Cause exception while getting updates.
Traceback (most recent call last):
  File "/usr/local/lib/python3.8/dist-packages/aiogram/dispatcher/dispatcher.py", line 383, in start_polling
    updates = await self.bot.get_updates(
  File "/usr/local/lib/python3.8/dist-packages/aiogram/bot/bot.py", line 97, in get_updates
    result = await self.request(api.Methods.GET_UPDATES, payload)
  File "/usr/local/lib/python3.8/dist-packages/aiogram/bot/base.py", line 208, in request
    return await api.make_request(self.session, self.server, self.__token, method, data, files,
  File "/usr/local/lib/python3.8/dist-packages/aiogram/bot/api.py", line 140, in make_request
    return check_result(method, response.content_type, response.status, await response.text())
  File "/usr/local/lib/python3.8/dist-packages/aiogram/bot/api.py", line 119, in check_result
    exceptions.ConflictError.detect(description)
  File "/usr/local/lib/python3.8/dist-packages/aiogram/utils/exceptions.py", line 140, in detect
    raise err(cls.text or description)
aiogram.utils.exceptions.TerminatedByOtherGetUpdates: Terminated by other getupdates request; make sure that only one bot instance is running
dispatcher.py [LINE:392] #ERROR    [2021-08-08 13:39:56,723]  Cause exception while getting updates.
Traceback (most recent call last):
  File "/usr/local/lib/python3.8/dist-packages/aiogram/dispatcher/dispatcher.py", line 383, in start_polling
    updates = await self.bot.get_updates(
  File "/usr/local/lib/python3.8/dist-packages/aiogram/bot/bot.py", line 97, in get_updates
    result = await self.request(api.Methods.GET_UPDATES, payload)
  File "/usr/local/lib/python3.8/dist-packages/aiogram/bot/base.py", line 208, in request
    return await api.make_request(self.session, self.server, self.__token, method, data, files,
  File "/usr/local/lib/python3.8/dist-packages/aiogram/bot/api.py", line 140, in make_request
    return check_result(method, response.content_type, response.status, await response.text())
  File "/usr/local/lib/python3.8/dist-packages/aiogram/bot/api.py", line 119, in check_result
    exceptions.ConflictError.detect(description)
  File "/usr/local/lib/python3.8/dist-packages/aiogram/utils/exceptions.py", line 140, in detect
    raise err(cls.text or description)
aiogram.utils.exceptions.TerminatedByOtherGetUpdates: Terminated by other getupdates request; make sure that only one bot instance is running
dispatcher.py [LINE:392] #ERROR    [2021-08-08 13:40:06,840]  Cause exception while getting updates.
Traceback (most recent call last):
  File "/usr/local/lib/python3.8/dist-packages/aiogram/dispatcher/dispatcher.py", line 383, in start_polling
    updates = await self.bot.get_updates(
  File "/usr/local/lib/python3.8/dist-packages/aiogram/bot/bot.py", line 97, in get_updates
    result = await self.request(api.Methods.GET_UPDATES, payload)
  File "/usr/local/lib/python3.8/dist-packages/aiogram/bot/base.py", line 208, in request
    return await api.make_request(self.session, self.server, self.__token, method, data, files,
  File "/usr/local/lib/python3.8/dist-packages/aiogram/bot/api.py", line 140, in make_request
    return check_result(method, response.content_type, response.status, await response.text())
  File "/usr/local/lib/python3.8/dist-packages/aiogram/bot/api.py", line 119, in check_result
    exceptions.ConflictError.detect(description)
  File "/usr/local/lib/python3.8/dist-packages/aiogram/utils/exceptions.py", line 140, in detect
    raise err(cls.text or description)
aiogram.utils.exceptions.TerminatedByOtherGetUpdates: Terminated by other getupdates request; make sure that only one bot instance is running
dispatcher.py [LINE:392] #ERROR    [2021-08-08 13:40:16,970]  Cause exception while getting updates.
Traceback (most recent call last):
  File "/usr/local/lib/python3.8/dist-packages/aiogram/dispatcher/dispatcher.py", line 383, in start_polling
    updates = await self.bot.get_updates(
  File "/usr/local/lib/python3.8/dist-packages/aiogram/bot/bot.py", line 97, in get_updates
    result = await self.request(api.Methods.GET_UPDATES, payload)
  File "/usr/local/lib/python3.8/dist-packages/aiogram/bot/base.py", line 208, in request
    return await api.make_request(self.session, self.server, self.__token, method, data, files,
  File "/usr/local/lib/python3.8/dist-packages/aiogram/bot/api.py", line 140, in make_request
    return check_result(method, response.content_type, response.status, await response.text())
  File "/usr/local/lib/python3.8/dist-packages/aiogram/bot/api.py", line 119, in check_result
    exceptions.ConflictError.detect(description)
  File "/usr/local/lib/python3.8/dist-packages/aiogram/utils/exceptions.py", line 140, in detect
    raise err(cls.text or description)
aiogram.utils.exceptions.TerminatedByOtherGetUpdates: Terminated by other getupdates request; make sure that only one bot instance is running
dispatcher.py [LINE:392] #ERROR    [2021-08-08 13:40:27,105]  Cause exception while getting updates.
Traceback (most recent call last):
  File "/usr/local/lib/python3.8/dist-packages/aiogram/dispatcher/dispatcher.py", line 383, in start_polling
    updates = await self.bot.get_updates(
  File "/usr/local/lib/python3.8/dist-packages/aiogram/bot/bot.py", line 97, in get_updates
    result = await self.request(api.Methods.GET_UPDATES, payload)
  File "/usr/local/lib/python3.8/dist-packages/aiogram/bot/base.py", line 208, in request
    return await api.make_request(self.session, self.server, self.__token, method, data, files,
  File "/usr/local/lib/python3.8/dist-packages/aiogram/bot/api.py", line 140, in make_request
    return check_result(method, response.content_type, response.status, await response.text())
  File "/usr/local/lib/python3.8/dist-packages/aiogram/bot/api.py", line 119, in check_result
    exceptions.ConflictError.detect(description)
  File "/usr/local/lib/python3.8/dist-packages/aiogram/utils/exceptions.py", line 140, in detect
    raise err(cls.text or description)
aiogram.utils.exceptions.TerminatedByOtherGetUpdates: Terminated by other getupdates request; make sure that only one bot instance is running
dispatcher.py [LINE:392] #ERROR    [2021-08-08 13:40:37,227]  Cause exception while getting updates.
Traceback (most recent call last):
  File "/usr/local/lib/python3.8/dist-packages/aiogram/dispatcher/dispatcher.py", line 383, in start_polling
    updates = await self.bot.get_updates(
  File "/usr/local/lib/python3.8/dist-packages/aiogram/bot/bot.py", line 97, in get_updates
    result = await self.request(api.Methods.GET_UPDATES, payload)
  File "/usr/local/lib/python3.8/dist-packages/aiogram/bot/base.py", line 208, in request
    return await api.make_request(self.session, self.server, self.__token, method, data, files,
  File "/usr/local/lib/python3.8/dist-packages/aiogram/bot/api.py", line 140, in make_request
    return check_result(method, response.content_type, response.status, await response.text())
  File "/usr/local/lib/python3.8/dist-packages/aiogram/bot/api.py", line 119, in check_result
    exceptions.ConflictError.detect(description)
  File "/usr/local/lib/python3.8/dist-packages/aiogram/utils/exceptions.py", line 140, in detect
    raise err(cls.text or description)
aiogram.utils.exceptions.TerminatedByOtherGetUpdates: Terminated by other getupdates request; make sure that only one bot instance is running
dispatcher.py [LINE:392] #ERROR    [2021-08-08 13:40:47,347]  Cause exception while getting updates.
Traceback (most recent call last):
  File "/usr/local/lib/python3.8/dist-packages/aiogram/dispatcher/dispatcher.py", line 383, in start_polling
    updates = await self.bot.get_updates(
  File "/usr/local/lib/python3.8/dist-packages/aiogram/bot/bot.py", line 97, in get_updates
    result = await self.request(api.Methods.GET_UPDATES, payload)
  File "/usr/local/lib/python3.8/dist-packages/aiogram/bot/base.py", line 208, in request
    return await api.make_request(self.session, self.server, self.__token, method, data, files,
  File "/usr/local/lib/python3.8/dist-packages/aiogram/bot/api.py", line 140, in make_request
    return check_result(method, response.content_type, response.status, await response.text())
  File "/usr/local/lib/python3.8/dist-packages/aiogram/bot/api.py", line 119, in check_result
    exceptions.ConflictError.detect(description)
  File "/usr/local/lib/python3.8/dist-packages/aiogram/utils/exceptions.py", line 140, in detect
    raise err(cls.text or description)
aiogram.utils.exceptions.TerminatedByOtherGetUpdates: Terminated by other getupdates request; make sure that only one bot instance is running
dispatcher.py [LINE:392] #ERROR    [2021-08-08 13:40:57,467]  Cause exception while getting updates.
Traceback (most recent call last):
  File "/usr/local/lib/python3.8/dist-packages/aiogram/dispatcher/dispatcher.py", line 383, in start_polling
    updates = await self.bot.get_updates(
  File "/usr/local/lib/python3.8/dist-packages/aiogram/bot/bot.py", line 97, in get_updates
    result = await self.request(api.Methods.GET_UPDATES, payload)
  File "/usr/local/lib/python3.8/dist-packages/aiogram/bot/base.py", line 208, in request
    return await api.make_request(self.session, self.server, self.__token, method, data, files,
  File "/usr/local/lib/python3.8/dist-packages/aiogram/bot/api.py", line 140, in make_request
    return check_result(method, response.content_type, response.status, await response.text())
  File "/usr/local/lib/python3.8/dist-packages/aiogram/bot/api.py", line 119, in check_result
    exceptions.ConflictError.detect(description)
  File "/usr/local/lib/python3.8/dist-packages/aiogram/utils/exceptions.py", line 140, in detect
    raise err(cls.text or description)
aiogram.utils.exceptions.TerminatedByOtherGetUpdates: Terminated by other getupdates request; make sure that only one bot instance is running
dispatcher.py [LINE:392] #ERROR    [2021-08-08 13:41:07,587]  Cause exception while getting updates.
Traceback (most recent call last):
  File "/usr/local/lib/python3.8/dist-packages/aiogram/dispatcher/dispatcher.py", line 383, in start_polling
    updates = await self.bot.get_updates(
  File "/usr/local/lib/python3.8/dist-packages/aiogram/bot/bot.py", line 97, in get_updates
    result = await self.request(api.Methods.GET_UPDATES, payload)
  File "/usr/local/lib/python3.8/dist-packages/aiogram/bot/base.py", line 208, in request
    return await api.make_request(self.session, self.server, self.__token, method, data, files,
  File "/usr/local/lib/python3.8/dist-packages/aiogram/bot/api.py", line 140, in make_request
    return check_result(method, response.content_type, response.status, await response.text())
  File "/usr/local/lib/python3.8/dist-packages/aiogram/bot/api.py", line 119, in check_result
    exceptions.ConflictError.detect(description)
  File "/usr/local/lib/python3.8/dist-packages/aiogram/utils/exceptions.py", line 140, in detect
    raise err(cls.text or description)
aiogram.utils.exceptions.TerminatedByOtherGetUpdates: Terminated by other getupdates request; make sure that only one bot instance is running
dispatcher.py [LINE:392] #ERROR    [2021-08-08 13:41:17,706]  Cause exception while getting updates.
Traceback (most recent call last):
  File "/usr/local/lib/python3.8/dist-packages/aiogram/dispatcher/dispatcher.py", line 383, in start_polling
    updates = await self.bot.get_updates(
  File "/usr/local/lib/python3.8/dist-packages/aiogram/bot/bot.py", line 97, in get_updates
    result = await self.request(api.Methods.GET_UPDATES, payload)
  File "/usr/local/lib/python3.8/dist-packages/aiogram/bot/base.py", line 208, in request
    return await api.make_request(self.session, self.server, self.__token, method, data, files,
  File "/usr/local/lib/python3.8/dist-packages/aiogram/bot/api.py", line 140, in make_request
    return check_result(method, response.content_type, response.status, await response.text())
  File "/usr/local/lib/python3.8/dist-packages/aiogram/bot/api.py", line 119, in check_result
    exceptions.ConflictError.detect(description)
  File "/usr/local/lib/python3.8/dist-packages/aiogram/utils/exceptions.py", line 140, in detect
    raise err(cls.text or description)
aiogram.utils.exceptions.TerminatedByOtherGetUpdates: Terminated by other getupdates request; make sure that only one bot instance is running
dispatcher.py [LINE:392] #ERROR    [2021-08-08 13:41:27,828]  Cause exception while getting updates.
Traceback (most recent call last):
  File "/usr/local/lib/python3.8/dist-packages/aiogram/dispatcher/dispatcher.py", line 383, in start_polling
    updates = await self.bot.get_updates(
  File "/usr/local/lib/python3.8/dist-packages/aiogram/bot/bot.py", line 97, in get_updates
    result = await self.request(api.Methods.GET_UPDATES, payload)
  File "/usr/local/lib/python3.8/dist-packages/aiogram/bot/base.py", line 208, in request
    return await api.make_request(self.session, self.server, self.__token, method, data, files,
  File "/usr/local/lib/python3.8/dist-packages/aiogram/bot/api.py", line 140, in make_request
    return check_result(method, response.content_type, response.status, await response.text())
  File "/usr/local/lib/python3.8/dist-packages/aiogram/bot/api.py", line 119, in check_result
    exceptions.ConflictError.detect(description)
  File "/usr/local/lib/python3.8/dist-packages/aiogram/utils/exceptions.py", line 140, in detect
    raise err(cls.text or description)
aiogram.utils.exceptions.TerminatedByOtherGetUpdates: Terminated by other getupdates request; make sure that only one bot instance is running
dispatcher.py [LINE:392] #ERROR    [2021-08-08 13:41:37,946]  Cause exception while getting updates.
Traceback (most recent call last):
  File "/usr/local/lib/python3.8/dist-packages/aiogram/dispatcher/dispatcher.py", line 383, in start_polling
    updates = await self.bot.get_updates(
  File "/usr/local/lib/python3.8/dist-packages/aiogram/bot/bot.py", line 97, in get_updates
    result = await self.request(api.Methods.GET_UPDATES, payload)
  File "/usr/local/lib/python3.8/dist-packages/aiogram/bot/base.py", line 208, in request
    return await api.make_request(self.session, self.server, self.__token, method, data, files,
  File "/usr/local/lib/python3.8/dist-packages/aiogram/bot/api.py", line 140, in make_request
    return check_result(method, response.content_type, response.status, await response.text())
  File "/usr/local/lib/python3.8/dist-packages/aiogram/bot/api.py", line 119, in check_result
    exceptions.ConflictError.detect(description)
  File "/usr/local/lib/python3.8/dist-packages/aiogram/utils/exceptions.py", line 140, in detect
    raise err(cls.text or description)
aiogram.utils.exceptions.TerminatedByOtherGetUpdates: Terminated by other getupdates request; make sure that only one bot instance is running
bot.py [LINE:52] #INFO     [2021-08-08 13:41:40,134]  Starting bot
dispatcher.py [LINE:360] #INFO     [2021-08-08 13:41:40,156]  Start polling.
dispatcher.py [LINE:392] #ERROR    [2021-08-08 13:41:48,347]  Cause exception while getting updates.
Traceback (most recent call last):
  File "/usr/local/lib/python3.8/dist-packages/aiogram/dispatcher/dispatcher.py", line 383, in start_polling
    updates = await self.bot.get_updates(
  File "/usr/local/lib/python3.8/dist-packages/aiogram/bot/bot.py", line 97, in get_updates
    result = await self.request(api.Methods.GET_UPDATES, payload)
  File "/usr/local/lib/python3.8/dist-packages/aiogram/bot/base.py", line 208, in request
    return await api.make_request(self.session, self.server, self.__token, method, data, files,
  File "/usr/local/lib/python3.8/dist-packages/aiogram/bot/api.py", line 140, in make_request
    return check_result(method, response.content_type, response.status, await response.text())
  File "/usr/local/lib/python3.8/dist-packages/aiogram/bot/api.py", line 119, in check_result
    exceptions.ConflictError.detect(description)
  File "/usr/local/lib/python3.8/dist-packages/aiogram/utils/exceptions.py", line 140, in detect
    raise err(cls.text or description)
aiogram.utils.exceptions.TerminatedByOtherGetUpdates: Terminated by other getupdates request; make sure that only one bot instance is running
dispatcher.py [LINE:392] #ERROR    [2021-08-08 13:41:58,481]  Cause exception while getting updates.
Traceback (most recent call last):
  File "/usr/local/lib/python3.8/dist-packages/aiogram/dispatcher/dispatcher.py", line 383, in start_polling
    updates = await self.bot.get_updates(
  File "/usr/local/lib/python3.8/dist-packages/aiogram/bot/bot.py", line 97, in get_updates
    result = await self.request(api.Methods.GET_UPDATES, payload)
  File "/usr/local/lib/python3.8/dist-packages/aiogram/bot/base.py", line 208, in request
    return await api.make_request(self.session, self.server, self.__token, method, data, files,
  File "/usr/local/lib/python3.8/dist-packages/aiogram/bot/api.py", line 140, in make_request
    return check_result(method, response.content_type, response.status, await response.text())
  File "/usr/local/lib/python3.8/dist-packages/aiogram/bot/api.py", line 119, in check_result
    exceptions.ConflictError.detect(description)
  File "/usr/local/lib/python3.8/dist-packages/aiogram/utils/exceptions.py", line 140, in detect
    raise err(cls.text or description)
aiogram.utils.exceptions.TerminatedByOtherGetUpdates: Terminated by other getupdates request; make sure that only one bot instance is running
dispatcher.py [LINE:392] #ERROR    [2021-08-08 13:42:08,612]  Cause exception while getting updates.
Traceback (most recent call last):
  File "/usr/local/lib/python3.8/dist-packages/aiogram/dispatcher/dispatcher.py", line 383, in start_polling
    updates = await self.bot.get_updates(
  File "/usr/local/lib/python3.8/dist-packages/aiogram/bot/bot.py", line 97, in get_updates
    result = await self.request(api.Methods.GET_UPDATES, payload)
  File "/usr/local/lib/python3.8/dist-packages/aiogram/bot/base.py", line 208, in request
    return await api.make_request(self.session, self.server, self.__token, method, data, files,
  File "/usr/local/lib/python3.8/dist-packages/aiogram/bot/api.py", line 140, in make_request
    return check_result(method, response.content_type, response.status, await response.text())
  File "/usr/local/lib/python3.8/dist-packages/aiogram/bot/api.py", line 119, in check_result
    exceptions.ConflictError.detect(description)
  File "/usr/local/lib/python3.8/dist-packages/aiogram/utils/exceptions.py", line 140, in detect
    raise err(cls.text or description)
aiogram.utils.exceptions.TerminatedByOtherGetUpdates: Terminated by other getupdates request; make sure that only one bot instance is running
dispatcher.py [LINE:392] #ERROR    [2021-08-08 13:42:18,740]  Cause exception while getting updates.
Traceback (most recent call last):
  File "/usr/local/lib/python3.8/dist-packages/aiogram/dispatcher/dispatcher.py", line 383, in start_polling
    updates = await self.bot.get_updates(
  File "/usr/local/lib/python3.8/dist-packages/aiogram/bot/bot.py", line 97, in get_updates
    result = await self.request(api.Methods.GET_UPDATES, payload)
  File "/usr/local/lib/python3.8/dist-packages/aiogram/bot/base.py", line 208, in request
    return await api.make_request(self.session, self.server, self.__token, method, data, files,
  File "/usr/local/lib/python3.8/dist-packages/aiogram/bot/api.py", line 140, in make_request
    return check_result(method, response.content_type, response.status, await response.text())
  File "/usr/local/lib/python3.8/dist-packages/aiogram/bot/api.py", line 119, in check_result
    exceptions.ConflictError.detect(description)
  File "/usr/local/lib/python3.8/dist-packages/aiogram/utils/exceptions.py", line 140, in detect
    raise err(cls.text or description)
aiogram.utils.exceptions.TerminatedByOtherGetUpdates: Terminated by other getupdates request; make sure that only one bot instance is running
dispatcher.py [LINE:392] #ERROR    [2021-08-08 13:42:28,908]  Cause exception while getting updates.
Traceback (most recent call last):
  File "/usr/local/lib/python3.8/dist-packages/aiogram/dispatcher/dispatcher.py", line 383, in start_polling
    updates = await self.bot.get_updates(
  File "/usr/local/lib/python3.8/dist-packages/aiogram/bot/bot.py", line 97, in get_updates
    result = await self.request(api.Methods.GET_UPDATES, payload)
  File "/usr/local/lib/python3.8/dist-packages/aiogram/bot/base.py", line 208, in request
    return await api.make_request(self.session, self.server, self.__token, method, data, files,
  File "/usr/local/lib/python3.8/dist-packages/aiogram/bot/api.py", line 140, in make_request
    return check_result(method, response.content_type, response.status, await response.text())
  File "/usr/local/lib/python3.8/dist-packages/aiogram/bot/api.py", line 119, in check_result
    exceptions.ConflictError.detect(description)
  File "/usr/local/lib/python3.8/dist-packages/aiogram/utils/exceptions.py", line 140, in detect
    raise err(cls.text or description)
aiogram.utils.exceptions.TerminatedByOtherGetUpdates: Terminated by other getupdates request; make sure that only one bot instance is running
dispatcher.py [LINE:392] #ERROR    [2021-08-08 13:42:39,891]  Cause exception while getting updates.
Traceback (most recent call last):
  File "/usr/local/lib/python3.8/dist-packages/aiogram/dispatcher/dispatcher.py", line 383, in start_polling
    updates = await self.bot.get_updates(
  File "/usr/local/lib/python3.8/dist-packages/aiogram/bot/bot.py", line 97, in get_updates
    result = await self.request(api.Methods.GET_UPDATES, payload)
  File "/usr/local/lib/python3.8/dist-packages/aiogram/bot/base.py", line 208, in request
    return await api.make_request(self.session, self.server, self.__token, method, data, files,
  File "/usr/local/lib/python3.8/dist-packages/aiogram/bot/api.py", line 140, in make_request
    return check_result(method, response.content_type, response.status, await response.text())
  File "/usr/local/lib/python3.8/dist-packages/aiogram/bot/api.py", line 119, in check_result
    exceptions.ConflictError.detect(description)
  File "/usr/local/lib/python3.8/dist-packages/aiogram/utils/exceptions.py", line 140, in detect
    raise err(cls.text or description)
aiogram.utils.exceptions.TerminatedByOtherGetUpdates: Terminated by other getupdates request; make sure that only one bot instance is running
dispatcher.py [LINE:392] #ERROR    [2021-08-08 13:42:50,014]  Cause exception while getting updates.
Traceback (most recent call last):
  File "/usr/local/lib/python3.8/dist-packages/aiogram/dispatcher/dispatcher.py", line 383, in start_polling
    updates = await self.bot.get_updates(
  File "/usr/local/lib/python3.8/dist-packages/aiogram/bot/bot.py", line 97, in get_updates
    result = await self.request(api.Methods.GET_UPDATES, payload)
  File "/usr/local/lib/python3.8/dist-packages/aiogram/bot/base.py", line 208, in request
    return await api.make_request(self.session, self.server, self.__token, method, data, files,
  File "/usr/local/lib/python3.8/dist-packages/aiogram/bot/api.py", line 140, in make_request
    return check_result(method, response.content_type, response.status, await response.text())
  File "/usr/local/lib/python3.8/dist-packages/aiogram/bot/api.py", line 119, in check_result
    exceptions.ConflictError.detect(description)
  File "/usr/local/lib/python3.8/dist-packages/aiogram/utils/exceptions.py", line 140, in detect
    raise err(cls.text or description)
aiogram.utils.exceptions.TerminatedByOtherGetUpdates: Terminated by other getupdates request; make sure that only one bot instance is running
dispatcher.py [LINE:392] #ERROR    [2021-08-08 13:43:00,144]  Cause exception while getting updates.
Traceback (most recent call last):
  File "/usr/local/lib/python3.8/dist-packages/aiogram/dispatcher/dispatcher.py", line 383, in start_polling
    updates = await self.bot.get_updates(
  File "/usr/local/lib/python3.8/dist-packages/aiogram/bot/bot.py", line 97, in get_updates
    result = await self.request(api.Methods.GET_UPDATES, payload)
  File "/usr/local/lib/python3.8/dist-packages/aiogram/bot/base.py", line 208, in request
    return await api.make_request(self.session, self.server, self.__token, method, data, files,
  File "/usr/local/lib/python3.8/dist-packages/aiogram/bot/api.py", line 140, in make_request
    return check_result(method, response.content_type, response.status, await response.text())
  File "/usr/local/lib/python3.8/dist-packages/aiogram/bot/api.py", line 119, in check_result
    exceptions.ConflictError.detect(description)
  File "/usr/local/lib/python3.8/dist-packages/aiogram/utils/exceptions.py", line 140, in detect
    raise err(cls.text or description)
aiogram.utils.exceptions.TerminatedByOtherGetUpdates: Terminated by other getupdates request; make sure that only one bot instance is running
dispatcher.py [LINE:392] #ERROR    [2021-08-08 13:43:10,285]  Cause exception while getting updates.
Traceback (most recent call last):
  File "/usr/local/lib/python3.8/dist-packages/aiogram/dispatcher/dispatcher.py", line 383, in start_polling
    updates = await self.bot.get_updates(
  File "/usr/local/lib/python3.8/dist-packages/aiogram/bot/bot.py", line 97, in get_updates
    result = await self.request(api.Methods.GET_UPDATES, payload)
  File "/usr/local/lib/python3.8/dist-packages/aiogram/bot/base.py", line 208, in request
    return await api.make_request(self.session, self.server, self.__token, method, data, files,
  File "/usr/local/lib/python3.8/dist-packages/aiogram/bot/api.py", line 140, in make_request
    return check_result(method, response.content_type, response.status, await response.text())
  File "/usr/local/lib/python3.8/dist-packages/aiogram/bot/api.py", line 119, in check_result
    exceptions.ConflictError.detect(description)
  File "/usr/local/lib/python3.8/dist-packages/aiogram/utils/exceptions.py", line 140, in detect
    raise err(cls.text or description)
aiogram.utils.exceptions.TerminatedByOtherGetUpdates: Terminated by other getupdates request; make sure that only one bot instance is running
dispatcher.py [LINE:392] #ERROR    [2021-08-08 13:43:20,427]  Cause exception while getting updates.
Traceback (most recent call last):
  File "/usr/local/lib/python3.8/dist-packages/aiogram/dispatcher/dispatcher.py", line 383, in start_polling
    updates = await self.bot.get_updates(
  File "/usr/local/lib/python3.8/dist-packages/aiogram/bot/bot.py", line 97, in get_updates
    result = await self.request(api.Methods.GET_UPDATES, payload)
  File "/usr/local/lib/python3.8/dist-packages/aiogram/bot/base.py", line 208, in request
    return await api.make_request(self.session, self.server, self.__token, method, data, files,
  File "/usr/local/lib/python3.8/dist-packages/aiogram/bot/api.py", line 140, in make_request
    return check_result(method, response.content_type, response.status, await response.text())
  File "/usr/local/lib/python3.8/dist-packages/aiogram/bot/api.py", line 119, in check_result
    exceptions.ConflictError.detect(description)
  File "/usr/local/lib/python3.8/dist-packages/aiogram/utils/exceptions.py", line 140, in detect
    raise err(cls.text or description)
aiogram.utils.exceptions.TerminatedByOtherGetUpdates: Terminated by other getupdates request; make sure that only one bot instance is running
dispatcher.py [LINE:392] #ERROR    [2021-08-08 13:43:30,559]  Cause exception while getting updates.
Traceback (most recent call last):
  File "/usr/local/lib/python3.8/dist-packages/aiogram/dispatcher/dispatcher.py", line 383, in start_polling
    updates = await self.bot.get_updates(
  File "/usr/local/lib/python3.8/dist-packages/aiogram/bot/bot.py", line 97, in get_updates
    result = await self.request(api.Methods.GET_UPDATES, payload)
  File "/usr/local/lib/python3.8/dist-packages/aiogram/bot/base.py", line 208, in request
    return await api.make_request(self.session, self.server, self.__token, method, data, files,
  File "/usr/local/lib/python3.8/dist-packages/aiogram/bot/api.py", line 140, in make_request
    return check_result(method, response.content_type, response.status, await response.text())
  File "/usr/local/lib/python3.8/dist-packages/aiogram/bot/api.py", line 119, in check_result
    exceptions.ConflictError.detect(description)
  File "/usr/local/lib/python3.8/dist-packages/aiogram/utils/exceptions.py", line 140, in detect
    raise err(cls.text or description)
aiogram.utils.exceptions.TerminatedByOtherGetUpdates: Terminated by other getupdates request; make sure that only one bot instance is running
dispatcher.py [LINE:392] #ERROR    [2021-08-08 13:43:40,693]  Cause exception while getting updates.
Traceback (most recent call last):
  File "/usr/local/lib/python3.8/dist-packages/aiogram/dispatcher/dispatcher.py", line 383, in start_polling
    updates = await self.bot.get_updates(
  File "/usr/local/lib/python3.8/dist-packages/aiogram/bot/bot.py", line 97, in get_updates
    result = await self.request(api.Methods.GET_UPDATES, payload)
  File "/usr/local/lib/python3.8/dist-packages/aiogram/bot/base.py", line 208, in request
    return await api.make_request(self.session, self.server, self.__token, method, data, files,
  File "/usr/local/lib/python3.8/dist-packages/aiogram/bot/api.py", line 140, in make_request
    return check_result(method, response.content_type, response.status, await response.text())
  File "/usr/local/lib/python3.8/dist-packages/aiogram/bot/api.py", line 119, in check_result
    exceptions.ConflictError.detect(description)
  File "/usr/local/lib/python3.8/dist-packages/aiogram/utils/exceptions.py", line 140, in detect
    raise err(cls.text or description)
aiogram.utils.exceptions.TerminatedByOtherGetUpdates: Terminated by other getupdates request; make sure that only one bot instance is running
dispatcher.py [LINE:392] #ERROR    [2021-08-08 13:43:50,822]  Cause exception while getting updates.
Traceback (most recent call last):
  File "/usr/local/lib/python3.8/dist-packages/aiogram/dispatcher/dispatcher.py", line 383, in start_polling
    updates = await self.bot.get_updates(
  File "/usr/local/lib/python3.8/dist-packages/aiogram/bot/bot.py", line 97, in get_updates
    result = await self.request(api.Methods.GET_UPDATES, payload)
  File "/usr/local/lib/python3.8/dist-packages/aiogram/bot/base.py", line 208, in request
    return await api.make_request(self.session, self.server, self.__token, method, data, files,
  File "/usr/local/lib/python3.8/dist-packages/aiogram/bot/api.py", line 140, in make_request
    return check_result(method, response.content_type, response.status, await response.text())
  File "/usr/local/lib/python3.8/dist-packages/aiogram/bot/api.py", line 119, in check_result
    exceptions.ConflictError.detect(description)
  File "/usr/local/lib/python3.8/dist-packages/aiogram/utils/exceptions.py", line 140, in detect
    raise err(cls.text or description)
aiogram.utils.exceptions.TerminatedByOtherGetUpdates: Terminated by other getupdates request; make sure that only one bot instance is running
dispatcher.py [LINE:392] #ERROR    [2021-08-08 13:44:00,958]  Cause exception while getting updates.
Traceback (most recent call last):
  File "/usr/local/lib/python3.8/dist-packages/aiogram/dispatcher/dispatcher.py", line 383, in start_polling
    updates = await self.bot.get_updates(
  File "/usr/local/lib/python3.8/dist-packages/aiogram/bot/bot.py", line 97, in get_updates
    result = await self.request(api.Methods.GET_UPDATES, payload)
  File "/usr/local/lib/python3.8/dist-packages/aiogram/bot/base.py", line 208, in request
    return await api.make_request(self.session, self.server, self.__token, method, data, files,
  File "/usr/local/lib/python3.8/dist-packages/aiogram/bot/api.py", line 140, in make_request
    return check_result(method, response.content_type, response.status, await response.text())
  File "/usr/local/lib/python3.8/dist-packages/aiogram/bot/api.py", line 119, in check_result
    exceptions.ConflictError.detect(description)
  File "/usr/local/lib/python3.8/dist-packages/aiogram/utils/exceptions.py", line 140, in detect
    raise err(cls.text or description)
aiogram.utils.exceptions.TerminatedByOtherGetUpdates: Terminated by other getupdates request; make sure that only one bot instance is running
dispatcher.py [LINE:392] #ERROR    [2021-08-08 13:44:11,084]  Cause exception while getting updates.
Traceback (most recent call last):
  File "/usr/local/lib/python3.8/dist-packages/aiogram/dispatcher/dispatcher.py", line 383, in start_polling
    updates = await self.bot.get_updates(
  File "/usr/local/lib/python3.8/dist-packages/aiogram/bot/bot.py", line 97, in get_updates
    result = await self.request(api.Methods.GET_UPDATES, payload)
  File "/usr/local/lib/python3.8/dist-packages/aiogram/bot/base.py", line 208, in request
    return await api.make_request(self.session, self.server, self.__token, method, data, files,
  File "/usr/local/lib/python3.8/dist-packages/aiogram/bot/api.py", line 140, in make_request
    return check_result(method, response.content_type, response.status, await response.text())
  File "/usr/local/lib/python3.8/dist-packages/aiogram/bot/api.py", line 119, in check_result
    exceptions.ConflictError.detect(description)
  File "/usr/local/lib/python3.8/dist-packages/aiogram/utils/exceptions.py", line 140, in detect
    raise err(cls.text or description)
aiogram.utils.exceptions.TerminatedByOtherGetUpdates: Terminated by other getupdates request; make sure that only one bot instance is running
dispatcher.py [LINE:392] #ERROR    [2021-08-08 13:44:21,216]  Cause exception while getting updates.
Traceback (most recent call last):
  File "/usr/local/lib/python3.8/dist-packages/aiogram/dispatcher/dispatcher.py", line 383, in start_polling
    updates = await self.bot.get_updates(
  File "/usr/local/lib/python3.8/dist-packages/aiogram/bot/bot.py", line 97, in get_updates
    result = await self.request(api.Methods.GET_UPDATES, payload)
  File "/usr/local/lib/python3.8/dist-packages/aiogram/bot/base.py", line 208, in request
    return await api.make_request(self.session, self.server, self.__token, method, data, files,
  File "/usr/local/lib/python3.8/dist-packages/aiogram/bot/api.py", line 140, in make_request
    return check_result(method, response.content_type, response.status, await response.text())
  File "/usr/local/lib/python3.8/dist-packages/aiogram/bot/api.py", line 119, in check_result
    exceptions.ConflictError.detect(description)
  File "/usr/local/lib/python3.8/dist-packages/aiogram/utils/exceptions.py", line 140, in detect
    raise err(cls.text or description)
aiogram.utils.exceptions.TerminatedByOtherGetUpdates: Terminated by other getupdates request; make sure that only one bot instance is running
base_events.py [LINE:1707] #ERROR    [2021-08-08 21:46:19,196]  Task exception was never retrieved
future: <Task finished name='Task-1496' coro=<Dispatcher._process_polling_updates() done, defined at /usr/local/lib/python3.8/dist-packages/aiogram/dispatcher/dispatcher.py:409> exception=TypeError('cannot unpack non-iterable NoneType object')>
Traceback (most recent call last):
  File "/usr/local/lib/python3.8/dist-packages/aiogram/dispatcher/dispatcher.py", line 417, in _process_polling_updates
    for responses in itertools.chain.from_iterable(await self.process_updates(updates, fast)):
  File "/usr/local/lib/python3.8/dist-packages/aiogram/dispatcher/dispatcher.py", line 238, in process_updates
    return await asyncio.gather(*tasks)
  File "/usr/local/lib/python3.8/dist-packages/aiogram/dispatcher/handler.py", line 116, in notify
    response = await handler_obj.handler(*args, **partial_data)
  File "/usr/local/lib/python3.8/dist-packages/aiogram/dispatcher/dispatcher.py", line 286, in process_update
    return await self.callback_query_handlers.notify(update.callback_query)
  File "/usr/local/lib/python3.8/dist-packages/aiogram/dispatcher/handler.py", line 116, in notify
    response = await handler_obj.handler(*args, **partial_data)
  File "/home/alexuserdev/crypto_exchange_bot/tgbot/handlers/admin.py", line 23, in confirm_deposit
    user_id = await AdminDb.confirm_deposit_request(id)
  File "/home/alexuserdev/crypto_exchange_bot/tgbot/misc/db_api/database.py", line 309, in confirm_deposit_request
    id, user_id, currency, amount = await conn.fetchrow(query)
TypeError: cannot unpack non-iterable NoneType object
base_events.py [LINE:1707] #ERROR    [2021-08-08 21:46:21,060]  Task exception was never retrieved
future: <Task finished name='Task-1499' coro=<Dispatcher._process_polling_updates() done, defined at /usr/local/lib/python3.8/dist-packages/aiogram/dispatcher/dispatcher.py:409> exception=TypeError('cannot unpack non-iterable NoneType object')>
Traceback (most recent call last):
  File "/usr/local/lib/python3.8/dist-packages/aiogram/dispatcher/dispatcher.py", line 417, in _process_polling_updates
    for responses in itertools.chain.from_iterable(await self.process_updates(updates, fast)):
  File "/usr/local/lib/python3.8/dist-packages/aiogram/dispatcher/dispatcher.py", line 238, in process_updates
    return await asyncio.gather(*tasks)
  File "/usr/local/lib/python3.8/dist-packages/aiogram/dispatcher/handler.py", line 116, in notify
    response = await handler_obj.handler(*args, **partial_data)
  File "/usr/local/lib/python3.8/dist-packages/aiogram/dispatcher/dispatcher.py", line 286, in process_update
    return await self.callback_query_handlers.notify(update.callback_query)
  File "/usr/local/lib/python3.8/dist-packages/aiogram/dispatcher/handler.py", line 116, in notify
    response = await handler_obj.handler(*args, **partial_data)
  File "/home/alexuserdev/crypto_exchange_bot/tgbot/handlers/admin.py", line 23, in confirm_deposit
    user_id = await AdminDb.confirm_deposit_request(id)
  File "/home/alexuserdev/crypto_exchange_bot/tgbot/misc/db_api/database.py", line 309, in confirm_deposit_request
    id, user_id, currency, amount = await conn.fetchrow(query)
TypeError: cannot unpack non-iterable NoneType object
base_events.py [LINE:1707] #ERROR    [2021-08-25 14:09:07,194]  Task exception was never retrieved
future: <Task finished name='Task-74490' coro=<Dispatcher._process_polling_updates() done, defined at /usr/local/lib/python3.8/dist-packages/aiogram/dispatcher/dispatcher.py:409> exception=MessageNotModified('Message is not modified: specified new message content and reply markup are exactly the same as a current content and reply markup of the message')>
Traceback (most recent call last):
  File "/usr/local/lib/python3.8/dist-packages/aiogram/dispatcher/dispatcher.py", line 417, in _process_polling_updates
    for responses in itertools.chain.from_iterable(await self.process_updates(updates, fast)):
  File "/usr/local/lib/python3.8/dist-packages/aiogram/dispatcher/dispatcher.py", line 238, in process_updates
    return await asyncio.gather(*tasks)
  File "/usr/local/lib/python3.8/dist-packages/aiogram/dispatcher/handler.py", line 116, in notify
    response = await handler_obj.handler(*args, **partial_data)
  File "/usr/local/lib/python3.8/dist-packages/aiogram/dispatcher/dispatcher.py", line 286, in process_update
    return await self.callback_query_handlers.notify(update.callback_query)
  File "/usr/local/lib/python3.8/dist-packages/aiogram/dispatcher/handler.py", line 116, in notify
    response = await handler_obj.handler(*args, **partial_data)
  File "/home/alexuserdev/crypto_exchange_bot/tgbot/handlers/deposit.py", line 34, in choosed_method
    await call.message.edit_reply_markup(BalanceKeyboard.deposit_methods(method))
  File "/usr/local/lib/python3.8/dist-packages/aiogram/types/message.py", line 2712, in edit_reply_markup
    return await self.bot.edit_message_reply_markup(
  File "/usr/local/lib/python3.8/dist-packages/aiogram/bot/bot.py", line 2541, in edit_message_reply_markup
    result = await self.request(api.Methods.EDIT_MESSAGE_REPLY_MARKUP, payload)
  File "/usr/local/lib/python3.8/dist-packages/aiogram/bot/base.py", line 208, in request
    return await api.make_request(self.session, self.server, self.__token, method, data, files,
  File "/usr/local/lib/python3.8/dist-packages/aiogram/bot/api.py", line 140, in make_request
    return check_result(method, response.content_type, response.status, await response.text())
  File "/usr/local/lib/python3.8/dist-packages/aiogram/bot/api.py", line 115, in check_result
    exceptions.BadRequest.detect(description)
  File "/usr/local/lib/python3.8/dist-packages/aiogram/utils/exceptions.py", line 140, in detect
    raise err(cls.text or description)
aiogram.utils.exceptions.MessageNotModified: Message is not modified: specified new message content and reply markup are exactly the same as a current content and reply markup of the message
base_events.py [LINE:1707] #ERROR    [2021-08-25 14:09:19,539]  Task exception was never retrieved
future: <Task finished name='Task-74515' coro=<Dispatcher._process_polling_updates() done, defined at /usr/local/lib/python3.8/dist-packages/aiogram/dispatcher/dispatcher.py:409> exception=MessageNotModified('Message is not modified: specified new message content and reply markup are exactly the same as a current content and reply markup of the message')>
Traceback (most recent call last):
  File "/usr/local/lib/python3.8/dist-packages/aiogram/dispatcher/dispatcher.py", line 417, in _process_polling_updates
    for responses in itertools.chain.from_iterable(await self.process_updates(updates, fast)):
  File "/usr/local/lib/python3.8/dist-packages/aiogram/dispatcher/dispatcher.py", line 238, in process_updates
    return await asyncio.gather(*tasks)
  File "/usr/local/lib/python3.8/dist-packages/aiogram/dispatcher/handler.py", line 116, in notify
    response = await handler_obj.handler(*args, **partial_data)
  File "/usr/local/lib/python3.8/dist-packages/aiogram/dispatcher/dispatcher.py", line 286, in process_update
    return await self.callback_query_handlers.notify(update.callback_query)
  File "/usr/local/lib/python3.8/dist-packages/aiogram/dispatcher/handler.py", line 116, in notify
    response = await handler_obj.handler(*args, **partial_data)
  File "/home/alexuserdev/crypto_exchange_bot/tgbot/handlers/deposit.py", line 34, in choosed_method
    await call.message.edit_reply_markup(BalanceKeyboard.deposit_methods(method))
  File "/usr/local/lib/python3.8/dist-packages/aiogram/types/message.py", line 2712, in edit_reply_markup
    return await self.bot.edit_message_reply_markup(
  File "/usr/local/lib/python3.8/dist-packages/aiogram/bot/bot.py", line 2541, in edit_message_reply_markup
    result = await self.request(api.Methods.EDIT_MESSAGE_REPLY_MARKUP, payload)
  File "/usr/local/lib/python3.8/dist-packages/aiogram/bot/base.py", line 208, in request
    return await api.make_request(self.session, self.server, self.__token, method, data, files,
  File "/usr/local/lib/python3.8/dist-packages/aiogram/bot/api.py", line 140, in make_request
    return check_result(method, response.content_type, response.status, await response.text())
  File "/usr/local/lib/python3.8/dist-packages/aiogram/bot/api.py", line 115, in check_result
    exceptions.BadRequest.detect(description)
  File "/usr/local/lib/python3.8/dist-packages/aiogram/utils/exceptions.py", line 140, in detect
    raise err(cls.text or description)
aiogram.utils.exceptions.MessageNotModified: Message is not modified: specified new message content and reply markup are exactly the same as a current content and reply markup of the message
base_events.py [LINE:1707] #ERROR    [2021-08-25 18:57:40,768]  Task exception was never retrieved
future: <Task finished name='Task-75584' coro=<Dispatcher._process_polling_updates() done, defined at /usr/local/lib/python3.8/dist-packages/aiogram/dispatcher/dispatcher.py:409> exception=MessageCantBeDeleted("Message can't be deleted for everyone")>
Traceback (most recent call last):
  File "/usr/local/lib/python3.8/dist-packages/aiogram/dispatcher/dispatcher.py", line 417, in _process_polling_updates
    for responses in itertools.chain.from_iterable(await self.process_updates(updates, fast)):
  File "/usr/local/lib/python3.8/dist-packages/aiogram/dispatcher/dispatcher.py", line 238, in process_updates
    return await asyncio.gather(*tasks)
  File "/usr/local/lib/python3.8/dist-packages/aiogram/dispatcher/handler.py", line 116, in notify
    response = await handler_obj.handler(*args, **partial_data)
  File "/usr/local/lib/python3.8/dist-packages/aiogram/dispatcher/dispatcher.py", line 286, in process_update
    return await self.callback_query_handlers.notify(update.callback_query)
  File "/usr/local/lib/python3.8/dist-packages/aiogram/dispatcher/handler.py", line 116, in notify
    response = await handler_obj.handler(*args, **partial_data)
  File "/home/alexuserdev/crypto_exchange_bot/tgbot/handlers/deposit.py", line 111, in approve_payment
    await call.message.delete()
  File "/usr/local/lib/python3.8/dist-packages/aiogram/types/message.py", line 2793, in delete
    return await self.bot.delete_message(self.chat.id, self.message_id)
  File "/usr/local/lib/python3.8/dist-packages/aiogram/bot/bot.py", line 2589, in delete_message
    return await self.request(api.Methods.DELETE_MESSAGE, payload)
  File "/usr/local/lib/python3.8/dist-packages/aiogram/bot/base.py", line 208, in request
    return await api.make_request(self.session, self.server, self.__token, method, data, files,
  File "/usr/local/lib/python3.8/dist-packages/aiogram/bot/api.py", line 140, in make_request
    return check_result(method, response.content_type, response.status, await response.text())
  File "/usr/local/lib/python3.8/dist-packages/aiogram/bot/api.py", line 115, in check_result
    exceptions.BadRequest.detect(description)
  File "/usr/local/lib/python3.8/dist-packages/aiogram/utils/exceptions.py", line 140, in detect
    raise err(cls.text or description)
aiogram.utils.exceptions.MessageCantBeDeleted: Message can't be deleted for everyone
base_events.py [LINE:1707] #ERROR    [2021-08-25 19:06:16,893]  Task exception was never retrieved
future: <Task finished name='Task-75625' coro=<Dispatcher._process_polling_updates() done, defined at /usr/local/lib/python3.8/dist-packages/aiogram/dispatcher/dispatcher.py:409> exception=MessageCantBeDeleted("Message can't be deleted for everyone")>
Traceback (most recent call last):
  File "/usr/local/lib/python3.8/dist-packages/aiogram/dispatcher/dispatcher.py", line 417, in _process_polling_updates
    for responses in itertools.chain.from_iterable(await self.process_updates(updates, fast)):
  File "/usr/local/lib/python3.8/dist-packages/aiogram/dispatcher/dispatcher.py", line 238, in process_updates
    return await asyncio.gather(*tasks)
  File "/usr/local/lib/python3.8/dist-packages/aiogram/dispatcher/handler.py", line 116, in notify
    response = await handler_obj.handler(*args, **partial_data)
  File "/usr/local/lib/python3.8/dist-packages/aiogram/dispatcher/dispatcher.py", line 286, in process_update
    return await self.callback_query_handlers.notify(update.callback_query)
  File "/usr/local/lib/python3.8/dist-packages/aiogram/dispatcher/handler.py", line 116, in notify
    response = await handler_obj.handler(*args, **partial_data)
  File "/home/alexuserdev/crypto_exchange_bot/tgbot/handlers/deposit.py", line 111, in approve_payment
    await call.message.delete()
  File "/usr/local/lib/python3.8/dist-packages/aiogram/types/message.py", line 2793, in delete
    return await self.bot.delete_message(self.chat.id, self.message_id)
  File "/usr/local/lib/python3.8/dist-packages/aiogram/bot/bot.py", line 2589, in delete_message
    return await self.request(api.Methods.DELETE_MESSAGE, payload)
  File "/usr/local/lib/python3.8/dist-packages/aiogram/bot/base.py", line 208, in request
    return await api.make_request(self.session, self.server, self.__token, method, data, files,
  File "/usr/local/lib/python3.8/dist-packages/aiogram/bot/api.py", line 140, in make_request
    return check_result(method, response.content_type, response.status, await response.text())
  File "/usr/local/lib/python3.8/dist-packages/aiogram/bot/api.py", line 115, in check_result
    exceptions.BadRequest.detect(description)
  File "/usr/local/lib/python3.8/dist-packages/aiogram/utils/exceptions.py", line 140, in detect
    raise err(cls.text or description)
aiogram.utils.exceptions.MessageCantBeDeleted: Message can't be deleted for everyone
base_events.py [LINE:1707] #ERROR    [2021-08-25 19:51:20,230]  Task exception was never retrieved
future: <Task finished name='Task-75992' coro=<Dispatcher._process_polling_updates() done, defined at /usr/local/lib/python3.8/dist-packages/aiogram/dispatcher/dispatcher.py:409> exception=BinanceAPIException(<Response [401]>, 401, '{"code":-1002,"msg":"You are not authorized to execute this request."}')>
Traceback (most recent call last):
  File "/usr/local/lib/python3.8/dist-packages/aiogram/dispatcher/dispatcher.py", line 417, in _process_polling_updates
    for responses in itertools.chain.from_iterable(await self.process_updates(updates, fast)):
  File "/usr/local/lib/python3.8/dist-packages/aiogram/dispatcher/dispatcher.py", line 238, in process_updates
    return await asyncio.gather(*tasks)
  File "/usr/local/lib/python3.8/dist-packages/aiogram/dispatcher/handler.py", line 116, in notify
    response = await handler_obj.handler(*args, **partial_data)
  File "/usr/local/lib/python3.8/dist-packages/aiogram/dispatcher/dispatcher.py", line 286, in process_update
    return await self.callback_query_handlers.notify(update.callback_query)
  File "/usr/local/lib/python3.8/dist-packages/aiogram/dispatcher/handler.py", line 116, in notify
    response = await handler_obj.handler(*args, **partial_data)
  File "/home/alexuserdev/crypto_exchange_bot/tgbot/handlers/balance.py", line 102, in confirm_withdraw
    await binance_work.create_withdraw_request(call.message.chat.id,
  File "/home/alexuserdev/crypto_exchange_bot/tgbot/misc/binance_work.py", line 70, in create_withdraw_request
    client.withdraw(asset=currency,
  File "/usr/local/lib/python3.8/dist-packages/binance/client.py", line 2492, in withdraw
    return self._request_margin_api('post', 'capital/withdraw/apply', True, data=params)
  File "/usr/local/lib/python3.8/dist-packages/binance/client.py", line 364, in _request_margin_api
    return self._request(method, uri, signed, **kwargs)
  File "/usr/local/lib/python3.8/dist-packages/binance/client.py", line 315, in _request
    return self._handle_response(self.response)
  File "/usr/local/lib/python3.8/dist-packages/binance/client.py", line 324, in _handle_response
    raise BinanceAPIException(response, response.status_code, response.text)
binance.exceptions.BinanceAPIException: APIError(code=-1002): You are not authorized to execute this request.
base_events.py [LINE:1707] #ERROR    [2021-08-25 19:52:00,270]  Task exception was never retrieved
future: <Task finished name='Task-76026' coro=<Dispatcher._process_polling_updates() done, defined at /usr/local/lib/python3.8/dist-packages/aiogram/dispatcher/dispatcher.py:409> exception=BinanceAPIException(<Response [401]>, 401, '{"code":-1002,"msg":"You are not authorized to execute this request."}')>
Traceback (most recent call last):
  File "/usr/local/lib/python3.8/dist-packages/aiogram/dispatcher/dispatcher.py", line 417, in _process_polling_updates
    for responses in itertools.chain.from_iterable(await self.process_updates(updates, fast)):
  File "/usr/local/lib/python3.8/dist-packages/aiogram/dispatcher/dispatcher.py", line 238, in process_updates
    return await asyncio.gather(*tasks)
  File "/usr/local/lib/python3.8/dist-packages/aiogram/dispatcher/handler.py", line 116, in notify
    response = await handler_obj.handler(*args, **partial_data)
  File "/usr/local/lib/python3.8/dist-packages/aiogram/dispatcher/dispatcher.py", line 286, in process_update
    return await self.callback_query_handlers.notify(update.callback_query)
  File "/usr/local/lib/python3.8/dist-packages/aiogram/dispatcher/handler.py", line 116, in notify
    response = await handler_obj.handler(*args, **partial_data)
  File "/home/alexuserdev/crypto_exchange_bot/tgbot/handlers/balance.py", line 102, in confirm_withdraw
    await binance_work.create_withdraw_request(call.message.chat.id,
  File "/home/alexuserdev/crypto_exchange_bot/tgbot/misc/binance_work.py", line 70, in create_withdraw_request
    client.withdraw(asset=currency,
  File "/usr/local/lib/python3.8/dist-packages/binance/client.py", line 2492, in withdraw
    return self._request_margin_api('post', 'capital/withdraw/apply', True, data=params)
  File "/usr/local/lib/python3.8/dist-packages/binance/client.py", line 364, in _request_margin_api
    return self._request(method, uri, signed, **kwargs)
  File "/usr/local/lib/python3.8/dist-packages/binance/client.py", line 315, in _request
    return self._handle_response(self.response)
  File "/usr/local/lib/python3.8/dist-packages/binance/client.py", line 324, in _handle_response
    raise BinanceAPIException(response, response.status_code, response.text)
binance.exceptions.BinanceAPIException: APIError(code=-1002): You are not authorized to execute this request.
mtprotosender.py [LINE:221] #INFO     [2021-08-25 19:54:57,526]  Connecting to 149.154.167.51:443/TcpFull...
mtprotosender.py [LINE:272] #INFO     [2021-08-25 19:54:57,544]  Connection to 149.154.167.51:443/TcpFull complete!
mtprotosender.py [LINE:312] #INFO     [2021-08-25 19:54:57,994]  Disconnecting from 149.154.167.51:443/TcpFull...
mtprotosender.py [LINE:332] #INFO     [2021-08-25 19:54:57,995]  Disconnection from 149.154.167.51:443/TcpFull complete!
base_events.py [LINE:1707] #ERROR    [2021-08-25 19:57:24,134]  Task exception was never retrieved
future: <Task finished name='Task-76109' coro=<Dispatcher._process_polling_updates() done, defined at /usr/local/lib/python3.8/dist-packages/aiogram/dispatcher/dispatcher.py:409> exception=BadRequest('Location can be requested in private chats only')>
Traceback (most recent call last):
  File "/usr/local/lib/python3.8/dist-packages/aiogram/dispatcher/dispatcher.py", line 417, in _process_polling_updates
    for responses in itertools.chain.from_iterable(await self.process_updates(updates, fast)):
  File "/usr/local/lib/python3.8/dist-packages/aiogram/dispatcher/dispatcher.py", line 238, in process_updates
    return await asyncio.gather(*tasks)
  File "/usr/local/lib/python3.8/dist-packages/aiogram/dispatcher/handler.py", line 116, in notify
    response = await handler_obj.handler(*args, **partial_data)
  File "/usr/local/lib/python3.8/dist-packages/aiogram/dispatcher/dispatcher.py", line 259, in process_update
    return await self.message_handlers.notify(update.message)
  File "/usr/local/lib/python3.8/dist-packages/aiogram/dispatcher/handler.py", line 116, in notify
    response = await handler_obj.handler(*args, **partial_data)
  File "/home/alexuserdev/crypto_exchange_bot/tgbot/handlers/start.py", line 29, in start
    await message.answer("Please send your location",
  File "/usr/local/lib/python3.8/dist-packages/aiogram/types/message.py", line 361, in answer
    return await self.bot.send_message(
  File "/usr/local/lib/python3.8/dist-packages/aiogram/bot/bot.py", line 314, in send_message
    result = await self.request(api.Methods.SEND_MESSAGE, payload)
  File "/usr/local/lib/python3.8/dist-packages/aiogram/bot/base.py", line 208, in request
    return await api.make_request(self.session, self.server, self.__token, method, data, files,
  File "/usr/local/lib/python3.8/dist-packages/aiogram/bot/api.py", line 140, in make_request
    return check_result(method, response.content_type, response.status, await response.text())
  File "/usr/local/lib/python3.8/dist-packages/aiogram/bot/api.py", line 115, in check_result
    exceptions.BadRequest.detect(description)
  File "/usr/local/lib/python3.8/dist-packages/aiogram/utils/exceptions.py", line 141, in detect
    raise cls(description)
aiogram.utils.exceptions.BadRequest: Location can be requested in private chats only
